<?xml version="1.0" ?>
<sdf version="1.10">
  <world name="motor">
    <physics name="1ms" type="ignore">
      <max_step_size>0.001</max_step_size>
      <real_time_factor>1.0</real_time_factor>
    </physics>

    <plugin filename="gz-sim-physics-system"
      name="gz::sim::systems::Physics">
    </plugin>
    <plugin
      filename="gz-sim-sensors-system"
      name="gz::sim::systems::Sensors">
      <render_engine>ogre2</render_engine>
    </plugin>
    <plugin filename="gz-sim-user-commands-system"
      name="gz::sim::systems::UserCommands">
    </plugin>
    <plugin filename="gz-sim-scene-broadcaster-system"
      name="gz::sim::systems::SceneBroadcaster">
    </plugin>
    <plugin filename="gz-sim-imu-system"
      name="gz::sim::systems::Imu">
    </plugin>
    <plugin filename="gz-sim-navsat-system"
      name="gz::sim::systems::NavSat">
    </plugin>

    <scene>
      <ambient>1.0 1.0 1.0</ambient>
      <background>0.8 0.8 0.8</background>
      <sky></sky>
    </scene>

    <spherical_coordinates>
      <latitude_deg>-35.363262</latitude_deg>
      <longitude_deg>149.165237</longitude_deg>
      <elevation>584</elevation>
      <heading_deg>0</heading_deg>
      <surface_model>EARTH_WGS84</surface_model>
    </spherical_coordinates>

    <light type="directional" name="sun">
      <cast_shadows>true</cast_shadows>
      <pose>0 0 10 0 0 0</pose>
      <diffuse>0.8 0.8 0.8 1</diffuse>
      <specular>0.8 0.8 0.8 1</specular>
      <attenuation>
        <range>1000</range>
        <constant>0.9</constant>
        <linear>0.01</linear>
        <quadratic>0.001</quadratic>
      </attenuation>
      <direction>-0.5 0.1 -0.9</direction>
    </light>
   
    <model name="ground_plane">
      <static>true</static>
      <link name="link">
        <collision name="collision">
          <geometry>
            <plane>
              <normal>0 0 1</normal>
              <size>100 100</size>
            </plane>
          </geometry>
          <surface>
            <friction>
              <ode>
                <mu>1000</mu>
                <mu2>1000</mu2>
              </ode>
            </friction>
          </surface>
        </collision>
        <visual name="visual">
          <geometry>
            <plane>
              <normal>0 0 1</normal>
              <size>100 100</size>
            </plane>
          </geometry>
          <material>
            <ambient>0.8 0.8 0.8</ambient>
            <diffuse>0.8 0.8 0.8</diffuse>
            <specular>0.8 0.8 0.8</specular>
          </material>
        </visual>
      </link>
    </model>

    <model name="motor">
      <pose degrees="true">0 0 0.005 0 0 0</pose>
      <link name="base_link">
        <inertial>
          <mass>10.0</mass>
          <inertia>
            <ixx>0.002166667</ixx>
            <ixy>0</ixy>
            <ixz>0</ixz>
            <iyy>0.002166667</iyy>
            <iyz>0</iyz>
            <izz>0.004166667</izz>
          </inertia>
        </inertial>
        <collision name="collision">
          <geometry>
            <box>
              <size>0.05 0.05 0.01</size>
            </box>
          </geometry>
          <surface>
            <friction>
              <ode>
                <mu>1000</mu>
                <mu2>1000</mu2>
              </ode>
            </friction>
          </surface>
        </collision>
        <visual name="visual">
          <geometry>
            <box>
              <size>0.05 0.05 0.01</size>
            </box>
          </geometry>
          <material>
            <ambient>0.2 0.2 0.2</ambient>
            <diffuse>0.2 0.2 0.2</diffuse>
            <specular>0.01 0.01 0.01</specular>
          </material>
        </visual>
      </link>

      <link name="motor_link">
        <pose relative_to="base_link" degrees="true">0 0 0.0205 0 0 0</pose>
        <inertial>
          <mass>0.064</mass>
          <inertia>
            <ixx>8.19449E-06</ixx>
            <ixy>0</ixy>
            <ixz>0</ixz>
            <iyy>8.19449E-06</iyy>
            <iyz>0</iyz>
            <izz>6.13832E-06</izz>
          </inertia>
        </inertial>
        <collision name="collision">
          <geometry>
            <cylinder>
              <length>0.031</length>
              <radius>0.01385</radius>
            </cylinder>
          </geometry>
        </collision>
        <visual name="visual">
          <geometry>
            <cylinder>
              <length>0.031</length>
              <radius>0.01385</radius>
            </cylinder>
          </geometry>
          <material>
            <ambient>0 0 1</ambient>
            <diffuse>0 0 1</diffuse>
            <specular>0.01 0.01 0.01</specular>
          </material>
        </visual>
      </link>
      <joint name="motor_joint" type="revolute">
        <pose degrees="true">0 0 0 0 0 0</pose>
        <parent>base_link</parent>
        <child>motor_link</child>
        <axis>
          <xyz>0 0 1</xyz>
          <limit>
            <lower>-1.0e16</lower>
            <upper>1.0e16</upper>
          </limit>
          <dynamics>
            <damping>0.001</damping>
          </dynamics>
        </axis>
      </joint>

      <link name="blade_1_link">
        <pose relative_to="motor_link" degrees="true">0.0635 0 0.018 0 0 0</pose>
        <inertial>
          <mass>0.0065</mass>
          <inertia>
            <ixx>2.30208E-07</ixx>
            <ixy>0</ixy>
            <ixz>0</ixz>
            <iyy>8.75008E-06</iyy>
            <iyz>0</iyz>
            <izz>8.95321E-06</izz>
          </inertia>
        </inertial>
        <collision name="collision">
          <geometry>
            <box>
              <size>0.127 0.02 0.005</size>
            </box>
          </geometry>
        </collision>
        <visual name="visual">
          <geometry>
            <box>
              <size>0.127 0.02 0.005</size>
            </box>
          </geometry>
          <material>
            <ambient>0.01 0.01 0.01</ambient>
            <diffuse>0.01 0.01 0.01</diffuse>
            <specular>0.01 0.01 0.01</specular>
          </material>
        </visual>
      </link>
      <joint name="blade_1_joint" type="revolute">
        <pose degrees="true">0 0 0 0 0 0</pose>
        <parent>motor_link</parent>
        <child>blade_1_link</child>
        <axis>
          <xyz>0 0 1</xyz>
          <limit>
            <lower>0</lower>
            <upper>0</upper>
          </limit>
          <dynamics>
            <damping>0.1</damping>
          </dynamics>
        </axis>
      </joint>

      <link name="blade_2_link">
        <pose relative_to="motor_link" degrees="true">-0.0635 0 0.018 0 0 180</pose>
        <inertial>
          <mass>0.0065</mass>
          <inertia>
            <ixx>2.30208E-07</ixx>
            <ixy>0</ixy>
            <ixz>0</ixz>
            <iyy>8.75008E-06</iyy>
            <iyz>0</iyz>
            <izz>8.95321E-06</izz>
          </inertia>
        </inertial>
        <collision name="collision">
          <geometry>
            <box>
              <size>0.127 0.02 0.005</size>
            </box>
          </geometry>
        </collision>
        <visual name="visual">
          <geometry>
            <box>
              <size>0.127 0.02 0.005</size>
            </box>
          </geometry>
          <material>
            <ambient>0.01 0.01 0.01</ambient>
            <diffuse>0.01 0.01 0.01</diffuse>
            <specular>0.01 0.01 0.01</specular>
          </material>
        </visual>
      </link>
      <joint name="blade_2_joint" type="revolute">
        <pose degrees="true">0 0 0 0 0 0</pose>
        <parent>motor_link</parent>
        <child>blade_2_link</child>
        <axis>
          <xyz>0 0 1</xyz>
          <limit>
            <lower>0</lower>
            <upper>0</upper>
          </limit>
          <dynamics>
            <damping>0.1</damping>
          </dynamics>
        </axis>
      </joint>

      <plugin name="gz::sim::systems::JointStatePublisher"
          filename="gz-sim-joint-state-publisher-system">
      </plugin>

      <!-- <plugin name="gz::sim::systems::JointController"
          filename="gz-sim-joint-controller-system">
        <joint_name>motor_joint</joint_name>
        <initial_velocity>0.0</initial_velocity>
        <use_force_commands>1</use_force_commands>
        <use_actuator_msg>0</use_actuator_msg>
        <disable_braking>0</disable_braking>
        <topic>/motor_joint/cmd_vel</topic>
        <p_gain>0.20</p_gain>
        <i_gain>0</i_gain>
        <d_gain>0</d_gain>
        <i_max>0</i_max>
        <i_min>0</i_min>
        <cmd_max>2.5</cmd_max>
        <cmd_min>-2.5</cmd_min>
      </plugin> -->

      <!--
        T-Motor 2216 920KV as used on a Hexsoon 450
        KV 920 RPM/V = KV 96 rad/s/V
      -->
      <plugin name="MotorPlugin" filename="MotorPlugin">
        <joint_name>motor_joint</joint_name>
        <use_actuator_msg>0</use_actuator_msg>
        <disable_braking>0</disable_braking>
        <topic>/motor_joint/cmd_vel</topic>
        <p_gain>0.01</p_gain>
        <i_gain>0.01</i_gain>
        <d_gain>0</d_gain>
        <i_max>1</i_max>
        <i_min>-1</i_min>
        <cmd_max>5.0</cmd_max>
        <cmd_min>-5.0</cmd_min>
        <voltage_bat>16.0</voltage_bat>
        <speed_constant>96</speed_constant>
        <torque_constant>53</torque_constant>
        <resistance>0.115</resistance>
        <no_load_current>0.8</no_load_current>
      </plugin>

    <!-- lift-drag for ccw prop -->
    <plugin filename="gz-sim-lift-drag-system"
        name="gz::sim::systems::LiftDrag">
      <a0>0.3</a0>
      <alpha_stall>1.4</alpha_stall>
      <cla>4.2500</cla>
      <cda>0.10</cda>
      <cma>0.0</cma>
      <cla_stall>-0.025</cla_stall>
      <cda_stall>0.0</cda_stall>
      <cma_stall>0.0</cma_stall>
      <area>0.0013</area>
      <air_density>1.2041</air_density>
      <cp>0 0 0</cp>
      <forward>0 1 0</forward>
      <upward>0 0 1</upward>
      <link_name>blade_1_link</link_name>
      <visualize_forces>
        <visualize>1</visualize>
        <update_rate>1000</update_rate>
        <!-- <topic>/model/motor/link/blade_1_link/forces/lift_drag</topic> -->
      </visualize_forces>
    </plugin>
    <plugin filename="gz-sim-lift-drag-system"
        name="gz::sim::systems::LiftDrag">
      <a0>0.3</a0>
      <alpha_stall>1.4</alpha_stall>
      <cla>4.2500</cla>
      <cda>0.10</cda>
      <cma>0.0</cma>
      <cla_stall>-0.025</cla_stall>
      <cda_stall>0.0</cda_stall>
      <cma_stall>0.0</cma_stall>
      <area>0.0013</area>
      <air_density>1.2041</air_density>
      <cp>0 0 0</cp>
      <forward>0 1 0</forward>
      <upward>0 0 1</upward>
      <link_name>blade_2_link</link_name>
      <visualize_forces>
        <visualize>1</visualize>
        <update_rate>1000</update_rate>
        <!-- <topic>/model/motor/link/blade_2_link/forces/lift_drag</topic> -->
      </visualize_forces>
    </plugin>

    </model>

  </world>
</sdf>
