<?xml version="1.0" ?>
<!--
1. Services

/world/servo/list_parameters
/world/servo/get_parameter
/world/servo/set_parameter

2. List parameters

gz param -r /world/servo -l      

Listing parameters, registry namespace [/world/servo]...

ServoPlugin..i_gain            [gz_msgs.Double]
ServoPlugin..d_gain            [gz_msgs.Double]
ServoPlugin..p_gain            [gz_msgs.Double]

3. Set parameter

gz param -r /world/servo -s -n ServoPlugin..p_gain -t gz_msgs.Double -m "data: 1.0"


4. Notes
- cmd_offset is not a feed-forward parameter in the usual sense, as it is not
  multiplied by the input cmd. Instead it is simply a constant offset.

  out = cmd_offset (+ other terms)


-->
<sdf version="1.9">
  <world name="servo">
    <physics name="1ms" type="ignore">
      <max_step_size>0.001</max_step_size>
      <real_time_factor>1.0</real_time_factor>
    </physics>

    <plugin name="gz::sim::systems::Physics"
      filename="gz-sim-physics-system">
    </plugin>
    <plugin name="gz::sim::systems::Sensors"
      filename="gz-sim-sensors-system">
      <render_engine>ogre2</render_engine>
    </plugin>
    <plugin name="gz::sim::systems::UserCommands"
      filename="gz-sim-user-commands-system">
    </plugin>
    <plugin name="gz::sim::systems::SceneBroadcaster"
      filename="gz-sim-scene-broadcaster-system">
    </plugin>
    <plugin name="gz::sim::systems::Imu"
      filename="gz-sim-imu-system">
    </plugin>

    <scene>
      <ambient>1.0 1.0 1.0</ambient>
      <background>0.8 0.8 0.8</background>
      <sky></sky>
    </scene>

    <light type="directional" name="sun">
      <cast_shadows>true</cast_shadows>
      <pose>0 0 10 0 0 0</pose>
      <diffuse>0.8 0.8 0.8 1</diffuse>
      <specular>0.8 0.8 0.8 1</specular>
      <attenuation>
        <range>1000</range>
        <constant>0.9</constant>
        <linear>0.01</linear>
        <quadratic>0.001</quadratic>
      </attenuation>
      <direction>0.5 0.1 -0.9</direction>
    </light>

    <model name="ground_plane">
      <static>true</static>
      <link name="link">
        <collision name="collision">
          <geometry>
            <plane>
              <normal>0 0 1</normal>
              <size>100 100</size>
            </plane>
          </geometry>
        </collision>
        <visual name="visual">
          <geometry>
            <plane>
              <normal>0 0 1</normal>
              <size>100 100</size>
            </plane>
          </geometry>
          <material>
            <ambient>0.8 0.8 0.8 1</ambient>
            <diffuse>0.8 0.8 0.8 1</diffuse>
            <specular>0.8 0.8 0.8 1</specular>
          </material>
        </visual>
      </link>
    </model>

    <!-- servo -->
    <model name="servo">
      <pose degrees="true">0 0 4.5 0 0 0</pose>
      <link name="base_link">
        <inertial>
          <mass>100.0</mass>
          <inertia>
            <ixx>808.3333333</ixx>
            <ixy>0</ixy>
            <ixz>0</ixz>
            <iyy>683.3333333</iyy>
            <iyz>0</iyz>
            <izz>141.6666667</izz>
          </inertia>
        </inertial>
        <visual name="visual">
          <geometry>
            <box>
              <size>1 4 9</size>
            </box>
          </geometry>
        </visual>
        <collision name="collision">
          <geometry>
            <box>
              <size>1 4 9</size>
            </box>
          </geometry>
        </collision>
      </link>
      <joint name="world_fixed" type="fixed">
        <parent>world</parent>
        <child>base_link</child>
      </joint>

      <link name="servo_arm_link">
        <pose relative_to="servo_arm_joint" degrees="true">0 0 1.8 0 0 0</pose>
        <inertial>
          <mass>1</mass>
          <inertia>
            <ixx>1.093333333</ixx>
            <ixy>0</ixy>
            <ixz>0</ixz>
            <iyy>1.080833333</iyy>
            <iyz>0</iyz>
            <izz>0.014166667</izz>
          </inertia>
        </inertial>
        <visual name="visual">
          <geometry>
            <box>
              <size>0.1 0.4 3.6</size>
            </box>
          </geometry>
          <material>
            <ambient>0.2 0.8 0.2 1</ambient>
            <diffuse>0.8 0 0 1</diffuse>
          </material>
        </visual>
        <collision name="collision">
          <geometry>
            <box>
              <size>0.1 0.4 3.6</size>
            </box>
          </geometry>
        </collision>
      </link>
      <joint name="servo_arm_joint" type="revolute">
        <pose relative_to="base_link" degrees="true">-0.55 0 0 90 0 180</pose>
        <parent>base_link</parent>
        <child>servo_arm_link</child>
        <axis>
          <xyz>1 0 0</xyz>
          <limits>
            <lower>-1.570796</lower>
            <upper>1.570796</upper>
          </limits>
          <dynamics>
            <damping>0.001</damping>
          </dynamics>
        </axis>
      </joint>

      <!-- plugins -->
      <plugin name="gz::sim::systems::JointStatePublisher"
        filename="gz-sim-joint-state-publisher-system">
      </plugin>

      <plugin name="gz::sim::systems::JointPositionController"
        filename="gz-sim-joint-position-controller-system">
        <joint_name>servo_arm_joint</joint_name>
        <topic>/model/servo/joint/servo_arm_link/0/cmd_pos</topic>
        <initial_position>0</initial_position>
        <use_velocity_commands>0</use_velocity_commands>
        <p_gain>10</p_gain>
        <i_gain>0</i_gain>
        <d_gain>0</d_gain>
        <i_max>1</i_max>
        <i_min>-1</i_min>
        <cmd_max>1000</cmd_max>
        <cmd_min>-1000</cmd_min>
      </plugin>

    </model>

  </world>
</sdf>
